<sdf version='1.9'>
  <world name='pick_and_place_world'>
    <physics name='1ms' type='ignored'>
      <max_step_size>0.001</max_step_size>
      <real_time_factor>1</real_time_factor>
      <real_time_update_rate>1000</real_time_update_rate>
    </physics>
    <plugin name='gz::sim::systems::Physics' filename='ignition-gazebo-physics-system'/>
    <plugin name='gz::sim::systems::UserCommands' filename='ignition-gazebo-user-commands-system'/>
    <plugin name='gz::sim::systems::SceneBroadcaster' filename='ignition-gazebo-scene-broadcaster-system'/>
    <plugin name='gz::sim::systems::Contact' filename='ignition-gazebo-contact-system'/>
    <gravity>0 0 -9.8</gravity>
    <magnetic_field>6e-06 2.3e-05 -4.2e-05</magnetic_field>
    <atmosphere type='adiabatic'/>
    <scene>
      <ambient>0.4 0.4 0.4 1</ambient>
      <background>0.7 0.7 0.7 1</background>
      <shadows>true</shadows>
    </scene>

    <model name='ground_plane'>
      <static>true</static>
      <link name='link'>
        <collision name='collision'>
          <geometry>
            <plane>
              <normal>0 0 1</normal>
              <size>100 100</size>
            </plane>
          </geometry>
          <surface>
            <friction>
              <ode/>
            </friction>
            <bounce/>
            <contact/>
          </surface>
        </collision>
        <visual name='visual'>
          <geometry>
            <plane>
              <normal>0 0 1</normal>
              <size>100 100</size>
            </plane>
          </geometry>
          <material>
            <ambient>0.8 0.8 0.8 1</ambient>
            <diffuse>0.8 0.8 0.8 1</diffuse>
            <specular>0.8 0.8 0.8 1</specular>
          </material>
        </visual>
        <pose>0 0 0 0 -0 0</pose>
        <inertial>
          <pose>0 0 0 0 -0 0</pose>
          <mass>1</mass>
          <inertia>
            <ixx>1</ixx>
            <ixy>0</ixy>
            <ixz>0</ixz>
            <iyy>1</iyy>
            <iyz>0</iyz>
            <izz>1</izz>
          </inertia>
        </inertial>
        <enable_wind>false</enable_wind>
      </link>
      <pose>0 0 0 0 -0 0</pose>
      <self_collide>false</self_collide>
    </model>

    <!-- Hollow box 1 (bin) for pick-and-place -->
    <model name="bin1">
      <static>true</static>
      <!-- Base link (contains floor + walls as separate visuals/collisions) -->
      <link name="bin_link1">
        <!-- Floor -->
        <collision name="floor_collision1">
          <pose>0 0 0.01 0 0 0</pose> <!-- floor sits at z=0.01 (half of floor_thickness) -->
          <geometry>
            <box>
              <size>0.5 0.5 0.02</size> <!-- floor_thickness = 0.02 m -->
            </box>
          </geometry>
        </collision>
        <visual name="floor_visual1">
          <pose>0 0 0.01 0 0 0</pose>
          <geometry><box><size>0.5 0.5 0.02</size></box></geometry>
          <material><ambient>0.6 0.4 0.2 1</ambient><diffuse>0.6 0.4 0.2 1</diffuse></material>
        </visual>

        <!-- Walls: front, back, left, right -->
        <!-- NOTE: wall_thickness = 0.02 m, wall_height = 0.28 m (so internal height ~0.26 m) -->
        <!-- Front wall (+x direction) -->
        <collision name="wall_front_collision1">
          <pose>0.215 0 0.16 0 0 0</pose> <!-- halfX - thickness/2 = 0.25 - 0.035 => ~0.215 -->
          <geometry>
            <box>
              <size>0.04 0.5 0.28</size> <!-- thickness x depth x height -->
            </box>
          </geometry>
        </collision>
        <visual name="wall_front_visual1">
          <pose>0.215 0 0.16 0 0 0</pose>
          <geometry><box><size>0.04 0.5 0.28</size></box></geometry>
          <material><ambient>0 1 0 1</ambient><diffuse>0 1 0 1</diffuse></material>
        </visual>

        <!-- Back wall (-x direction) -->
        <collision name="wall_back_collision1">
          <pose>-0.215 0 0.16 0 0 0</pose>
          <geometry>
            <box><size>0.04 0.5 0.28</size></box>
          </geometry>
        </collision>
        <visual name="wall_back_visual1">
          <pose>-0.215 0 0.16 0 0 0</pose>
          <geometry><box><size>0.04 0.5 0.28</size></box></geometry>
          <material><ambient>0 1 0 1</ambient><diffuse>0 1 0 1</diffuse></material>
        </visual>

        <!-- Left wall (+y) -->
        <collision name="wall_left_collision1">
          <pose>0 0.215 0.16 0 0 0</pose>
          <geometry>
            <box><size>0.5 0.04 0.28</size></box>
          </geometry>
        </collision>
        <visual name="wall_left_visual1">
          <pose>0 0.215 0.16 0 0 0</pose>
          <geometry><box><size>0.5 0.04 0.28</size></box></geometry>
          <material><ambient>0 1 0 1</ambient><diffuse>0 1 0 1</diffuse></material>
        </visual>

        <!-- Right wall (-y) -->
        <collision name="wall_right_collision1">
          <pose>0 -0.215 0.16 0 0 0</pose>
          <geometry>
            <box><size>0.5 0.04 0.28</size></box>
          </geometry>
        </collision>
        <visual name="wall_right_visual1">
          <pose>0 -0.215 0.16 0 0 0</pose>
          <geometry><box><size>0.5 0.04 0.28</size></box></geometry>
          <material><ambient>0 1 0 1</ambient><diffuse>0 1 0 1</diffuse></material>    <!--<ambient>R G B A</ambient>-->
        </visual>

        <!-- recommended contact surface parameters (optional tweak) -->
        <surface>
          <friction>
            <ode/>
          </friction>
          <bounce/>
          <contact/>
        </surface>
      </link>

      <!-- Place the whole bin closer to the robot -->
      <pose>1.0 1.2 0 0 0 0</pose> <!-- x y z roll pitch yaw (meters, radians) -->
    </model>


    <!-- Hollow box 2 (bin) for pick-and-place -->
    <model name="bin2">
      <static>true</static>
      <!-- Base link (contains floor + walls as separate visuals/collisions) -->
      <link name="bin_link2">
        <!-- Floor -->
        <collision name="floor_collision2">
          <pose>0 0 0.01 0 0 0</pose> <!-- floor sits at z=0.01 (half of floor_thickness) -->
          <geometry>
            <box>
              <size>0.5 0.5 0.02</size> <!-- floor_thickness = 0.02 m -->
            </box>
          </geometry>
        </collision>
        <visual name="floor_visual2">
          <pose>0 0 0.01 0 0 0</pose>
          <geometry><box><size>0.5 0.5 0.02</size></box></geometry>
          <material><ambient>0.6 0.4 0.2 1</ambient><diffuse>0.6 0.4 0.2 1</diffuse></material>
        </visual>

        <!-- Walls: front, back, left, right -->
        <!-- NOTE: wall_thickness = 0.02 m, wall_height = 0.28 m (so internal height ~0.26 m) -->
        <!-- Front wall (+x direction) -->
        <collision name="wall_front_collision2">
          <pose>0.215 0 0.16 0 0 0</pose> <!-- halfX - thickness/2 = 0.25 - 0.035 => ~0.215 -->
          <geometry>
            <box>
              <size>0.04 0.5 0.28</size> <!-- thickness x depth x height -->
            </box>
          </geometry>
        </collision>
        <visual name="wall_front_visual2">
          <pose>0.215 0 0.16 0 0 0</pose>
          <geometry><box><size>0.04 0.5 0.28</size></box></geometry>
          <material><ambient>1 0 0 1</ambient><diffuse>1 0 0 1</diffuse></material>
        </visual>

        <!-- Back wall (-x direction) -->
        <collision name="wall_back_collision2">
          <pose>-0.215 0 0.16 0 0 0</pose>
          <geometry>
            <box><size>0.04 0.5 0.28</size></box>
          </geometry>
        </collision>
        <visual name="wall_back_visual2">
          <pose>-0.215 0 0.16 0 0 0</pose>
          <geometry><box><size>0.04 0.5 0.28</size></box></geometry>
          <material><ambient>1 0 0 1</ambient><diffuse>1 0 0 1</diffuse></material>
        </visual>

        <!-- Left wall (+y) -->
        <collision name="wall_left_collision2">
          <pose>0 0.215 0.16 0 0 0</pose>
          <geometry>
            <box><size>0.5 0.04 0.28</size></box>
          </geometry>
        </collision>
        <visual name="wall_left_visual2">
          <pose>0 0.215 0.16 0 0 0</pose>
          <geometry><box><size>0.5 0.04 0.28</size></box></geometry>
          <material><ambient>1 0 0 1</ambient><diffuse>1 0 0 1</diffuse></material>
        </visual>

        <!-- Right wall (-y) -->
        <collision name="wall_right_collision2">
          <pose>0 -0.215 0.16 0 0 0</pose>
          <geometry>
            <box><size>0.5 0.04 0.28</size></box>
          </geometry>
        </collision>
        <visual name="wall_right_visual2">
          <pose>0 -0.215 0.16 0 0 0</pose>
          <geometry><box><size>0.5 0.04 0.28</size></box></geometry>
          <material><ambient>1 0 0 1</ambient><diffuse>1 0 0 1</diffuse></material>    <!--<ambient>R G B A</ambient>-->
        </visual>

        <!-- recommended contact surface parameters (optional tweak) -->
        <surface>
          <friction>
            <ode/>
          </friction>
          <bounce/>
          <contact/>
        </surface>
      </link>

      <!-- Place the whole bin closer to the robot -->
      <pose>1.0 0 0 0 0 0</pose> <!-- x y z roll pitch yaw (meters, radians) -->
    </model>

    <!-- BIN 3: low rectangular tray (symmetrically enlarged) -->
    <model name="bin3">
      <static>true</static>
      <link name="bin3_link">

        <!-- floor: outer_x=0.8, outer_y=0.6, floor_thickness=0.02 -->
        <collision name="floor_collision3">
          <pose>0 0 0.01 0 0 0</pose>     <!-- floor sits at z = floor_thickness/2 (in model frame) -->
          <geometry>
            <box>
              <size>0.8 0.6 0.02</size>
            </box>
          </geometry>
        </collision>
        <visual name="floor_visual3">
          <pose>0 0 0.01 0 0 0</pose>
          <geometry><box><size>0.8 0.6 0.02</size></box></geometry>
          <material>
            <ambient>0.5 0.5 0.5 1</ambient>
            <diffuse>0.5 0.5 0.5 1</diffuse>
          </material>
        </visual>

        <!-- parameters used:
            outer_x = 0.8  -> half_x = 0.40
            outer_y = 0.6  -> half_y = 0.30
            thickness = 0.04 -> half_thick = 0.02
            wall_center_offset_x = half_x - half_thick = 0.38
            wall_center_offset_y = half_y - half_thick = 0.28
            wall_height = 0.12 -> wall_center_z = floor_thickness/2 + wall_height/2 = 0.01 + 0.06 = 0.07
        -->

        <!-- front wall (+x) -->
        <collision name="wall_front_collision3">
          <pose>0.38 0 0.07 0 0 0</pose>
          <geometry><box><size>0.04 0.6 0.12</size></box></geometry>
        </collision>
        <visual name="wall_front_visual3">
          <pose>0.38 0 0.07 0 0 0</pose>
          <geometry><box><size>0.04 0.6 0.12</size></box></geometry>
          <material><ambient>0.5 0.5 0.5 1</ambient><diffuse>0.5 0.5 0.5 1</diffuse></material>
        </visual>

        <!-- back wall (-x) -->
        <collision name="wall_back_collision3">
          <pose>-0.38 0 0.07 0 0 0</pose>
          <geometry><box><size>0.04 0.6 0.12</size></box></geometry>
        </collision>
        <visual name="wall_back_visual3">
          <pose>-0.38 0 0.07 0 0 0</pose>
          <geometry><box><size>0.04 0.6 0.12</size></box></geometry>
          <material><ambient>0.5 0.5 0.5 1</ambient><diffuse>0.5 0.5 0.5 1</diffuse></material>
        </visual>

        <!-- left wall (+y) -->
        <collision name="wall_left_collision3">
          <pose>0 0.28 0.07 0 0 0</pose>
          <geometry><box><size>0.8 0.04 0.12</size></box></geometry>
        </collision>
        <visual name="wall_left_visual3">
          <pose>0 0.28 0.07 0 0 0</pose>
          <geometry><box><size>0.8 0.04 0.12</size></box></geometry>
          <material><ambient>0.5 0.5 0.5 1</ambient><diffuse>0.5 0.5 0.5 1</diffuse></material>
        </visual>

        <!-- right wall (-y) -->
        <collision name="wall_right_collision3">
          <pose>0 -0.28 0.07 0 0 0</pose>
          <geometry><box><size>0.8 0.04 0.12</size></box></geometry>
        </collision>
        <visual name="wall_right_visual3">
          <pose>0 -0.28 0.07 0 0 0</pose>
          <geometry><box><size>0.8 0.04 0.12</size></box></geometry>
          <material><ambient>0.5 0.5 0.5 1</ambient><diffuse>0.5 0.5 0.5 1</diffuse></material>
        </visual>

        <surface>
          <friction><ode/></friction>
          <bounce/>
          <contact/>
        </surface>

      </link>

      <!-- model pose remains the same: this is the tray CENTER in world coordinates -->
      <pose>0.0 -1.2 0 0 0 3.14</pose>
    </model>

    <!-- 6 balls placed with margin from tray walls (world coordinates) -->
    <model name="ball_1_green">
      <static>false</static>
      <link name="link">
        <pose>0.2000 -1.3000 0.0700 0 0 0</pose>
        <collision name="collision"><geometry><sphere><radius>0.05</radius></sphere></geometry></collision>
        <visual name="visual">
          <geometry><sphere><radius>0.05</radius></sphere></geometry>
          <material><ambient>0 1 0 1</ambient><diffuse>0 1 0 1</diffuse></material>
        </visual>
      </link>
    </model>

    <model name="ball_2_red">
      <static>false</static>
      <link name="link">
        <pose>0.0000 -1.3000 0.0700 0 0 0</pose>
        <collision name="collision"><geometry><sphere><radius>0.05</radius></sphere></geometry></collision>
        <visual name="visual">
          <geometry><sphere><radius>0.05</radius></sphere></geometry>
          <material><ambient>1 0 0 1</ambient><diffuse>1 0 0 1</diffuse></material>
        </visual>
      </link>
    </model>

    <model name="ball_3_green">
      <static>false</static>
      <link name="link">
        <pose>-0.2000 -1.3000 0.0700 0 0 0</pose>
        <collision name="collision"><geometry><sphere><radius>0.05</radius></sphere></geometry></collision>
        <visual name="visual">
          <geometry><sphere><radius>0.05</radius></sphere></geometry>
          <material><ambient>0 1 0 1</ambient><diffuse>0 1 0 1</diffuse></material>
        </visual>
      </link>
    </model>

    <model name="ball_4_red">
      <static>false</static>
      <link name="link">
        <pose>0.2000 -1.1000 0.0700 0 0 0</pose>
        <collision name="collision"><geometry><sphere><radius>0.05</radius></sphere></geometry></collision>
        <visual name="visual">
          <geometry><sphere><radius>0.05</radius></sphere></geometry>
          <material><ambient>1 0 0 1</ambient><diffuse>1 0 0 1</diffuse></material>
        </visual>
      </link>
    </model>

    <model name="ball_5_green">
      <static>false</static>
      <link name="link">
        <pose>0.0000 -1.1000 0.0700 0 0 0</pose>
        <collision name="collision"><geometry><sphere><radius>0.05</radius></sphere></geometry></collision>
        <visual name="visual">
          <geometry><sphere><radius>0.05</radius></sphere></geometry>
          <material><ambient>0 1 0 1</ambient><diffuse>0 1 0 1</diffuse></material>
        </visual>
      </link>
    </model>

    <model name="ball_6_red">
      <static>false</static>
      <link name="link">
        <pose>-0.2000 -1.1000 0.0700 0 0 0</pose>
        <collision name="collision"><geometry><sphere><radius>0.05</radius></sphere></geometry></collision>
        <visual name="visual">
          <geometry><sphere><radius>0.05</radius></sphere></geometry>
          <material><ambient>1 0 0 1</ambient><diffuse>1 0 0 1</diffuse></material>
        </visual>
      </link>
    </model>




    <!-- Random ball -->
    <model name='blue_ball'>
      <static>false</static>
      <link name='link'>
        <pose>0.2 0 0.05 0 0 0</pose>
        <collision name='collision'>
          <geometry>
            <sphere>
              <radius>0.05</radius>
            </sphere>
          </geometry>
        </collision>
        <visual name='visual'>
          <geometry>
            <sphere>
              <radius>0.05</radius>
            </sphere>
          </geometry>
          <material>
            <ambient>0 0.5 1 1</ambient>
            <diffuse>0 0.5 1 1</diffuse>
          </material>
        </visual>
      </link>
    </model>

    <!-- Your existing robot model (unchanged content below) -->
    <model name='robot_6dof_arm'>
      <joint name='fixed_base_joint' type='fixed'>
        <pose>0 0 0 0 -0 0</pose>
        <parent>world</parent>
        <child>base_link</child>
      </joint>
      <link name='base_link'>
        <pose>0 0 0 0 -0 0</pose>
        <inertial>
          <pose>0 0 0 0 -0 0</pose>
          <mass>5</mass>
          <inertia>
            <ixx>0.013542</ixx>
            <ixy>0</ixy>
            <ixz>0</ixz>
            <iyy>0.013542</iyy>
            <iyz>0</iyz>
            <izz>0.025000000000000001</izz>
          </inertia>
        </inertial>
        <collision name='base_link_collision'>
          <pose>0 0 0.025 0 0 0</pose>
          <geometry>
            <cylinder>
              <length>0.050000000000000003</length>
              <radius>0.10000000000000001</radius>
            </cylinder>
          </geometry>
          <surface>
            <friction>
              <ode/>
            </friction>
            <bounce/>
            <contact/>
          </surface>
        </collision>
        <visual name='base_link_visual'>
          <pose>0 0 0.025 0 0 0</pose>
          <geometry>
            <cylinder>
              <length>0.050000000000000003</length>
              <radius>0.10000000000000001</radius>
            </cylinder>
          </geometry>
          <material>
            <diffuse>0.625 0.625 0.625 1</diffuse>
            <ambient>0.625 0.625 0.625 1</ambient>
          </material>
        </visual>
        <enable_wind>false</enable_wind>
      </link>
      <joint name='base_link_link1' type='revolute'>
        <pose>0 0 0 0 -0 0</pose>
        <parent>base_link</parent>
        <child>link_1</child>
        <axis>
          <xyz>0 0 1</xyz>
          <limit>
            <lower>-3.1415899999999999</lower>
            <upper>3.1415899999999999</upper>
            <effort>50</effort>
            <velocity>1000</velocity>
            <stiffness>100000000</stiffness>
            <dissipation>1</dissipation>
          </limit>
          <dynamics>
            <spring_reference>0</spring_reference>
            <spring_stiffness>0</spring_stiffness>
            <damping>0</damping>
            <friction>0</friction>
          </dynamics>
        </axis>
      </joint>
      <link name='link_1'>
        <pose>0 0 0.05 0 -0 1e-06</pose>
        <inertial>
          <pose>0 0 0 0 -0 0</pose>
          <mass>2</mass>
          <inertia>
            <ixx>0.012866000000000001</ixx>
            <ixy>0</ixy>
            <ixz>0</ixz>
            <iyy>0.012866000000000001</iyy>
            <iyz>0</iyz>
            <izz>0.0025000000000000001</izz>
          </inertia>
        </inertial>
        <collision name='link_1_collision'>
          <pose>0 0 0.132 0 0 0</pose>
          <geometry>
            <cylinder>
              <length>0.26400000000000001</length>
              <radius>0.050000000000000003</radius>
            </cylinder>
          </geometry>
          <surface>
            <friction>
              <ode/>
            </friction>
            <bounce/>
            <contact/>
          </surface>
        </collision>
        <visual name='link_1_visual'>
          <pose>0 0 0.132 0 0 0</pose>
          <geometry>
            <cylinder>
              <length>0.26400000000000001</length>
              <radius>0.050000000000000003</radius>
            </cylinder>
          </geometry>
          <material>
            <diffuse>0 0 1 1</diffuse>
            <ambient>0 0 1 1</ambient>
          </material>
        </visual>
        <enable_wind>false</enable_wind>
      </link>
      <joint name='link1_link2' type='revolute'>
        <pose>0 0 0 0 -0 0</pose>
        <parent>link_1</parent>
        <child>link_2</child>
        <axis>
          <xyz>0 1 0</xyz>
          <limit>
            <lower>-2.5</lower>
            <upper>2.5</upper>
            <effort>50</effort>
            <velocity>1000</velocity>
            <stiffness>100000000</stiffness>
            <dissipation>1</dissipation>
          </limit>
          <dynamics>
            <spring_reference>0</spring_reference>
            <spring_stiffness>0</spring_stiffness>
            <damping>0</damping>
            <friction>0</friction>
          </dynamics>
        </axis>
      </joint>
      <link name='link_2'>
        <pose>-0 0.1 0.264 -0 -0 1e-06</pose>
        <inertial>
          <pose>0 0 0 0 -0 0</pose>
          <mass>3</mass>
          <inertia>
            <ixx>0.1825</ixx>
            <ixy>0</ixy>
            <ixz>0</ixz>
            <iyy>0.1825</iyy>
            <iyz>0</iyz>
            <izz>0.0037499999999999999</izz>
          </inertia>
        </inertial>
        <collision name='link_2_collision'>
          <pose>0 0 0.425 0 0 0</pose>
          <geometry>
            <cylinder>
              <length>0.84999999999999998</length>
              <radius>0.050000000000000003</radius>
            </cylinder>
          </geometry>
          <surface>
            <friction>
              <ode/>
            </friction>
            <bounce/>
            <contact/>
          </surface>
        </collision>
        <visual name='link_2_visual'>
          <pose>0 0 0.425 0 0 0</pose>
          <geometry>
            <cylinder>
              <length>0.84999999999999998</length>
              <radius>0.050000000000000003</radius>
            </cylinder>
          </geometry>
          <material>
            <diffuse>0 1 0 1</diffuse>
            <ambient>0 1 0 1</ambient>
          </material>
        </visual>
        <enable_wind>false</enable_wind>
      </link>
      <joint name='link2_link3' type='revolute'>
        <pose>0 0 0 0 -0 0</pose>
        <parent>link_2</parent>
        <child>link_3</child>
        <axis>
          <xyz>0 1 0</xyz>
          <limit>
            <lower>-3.1400000000000001</lower>
            <upper>3.1400000000000001</upper>
            <effort>50</effort>
            <velocity>1000</velocity>
            <stiffness>100000000</stiffness>
            <dissipation>1</dissipation>
          </limit>
          <dynamics>
            <spring_reference>0</spring_reference>
            <spring_stiffness>0</spring_stiffness>
            <damping>0</damping>
            <friction>0</friction>
          </dynamics>
        </axis>
      </joint>
      <link name='link_3'>
        <pose>-0 -0 1.064 0 -3e-06 1e-06</pose>
        <inertial>
          <pose>0 0 0 0 -0 0</pose>
          <mass>2.5</mass>
          <inertia>
            <ixx>0.097895999999999997</ixx>
            <ixy>0</ixy>
            <ixz>0</ixz>
            <iyy>0.097895999999999997</iyy>
            <iyz>0</iyz>
            <izz>0.0031250000000000002</izz>
          </inertia>
        </inertial>
        <collision name='link_3_collision'>
          <pose>0 0 0.34 0 0 0</pose>
          <geometry>
            <cylinder>
              <length>0.68000000000000005</length>
              <radius>0.050000000000000003</radius>
            </cylinder>
          </geometry>
          <surface>
            <friction>
              <ode/>
            </friction>
            <bounce/>
            <contact/>
          </surface>
        </collision>
        <visual name='link_3_visual'>
          <pose>0 0 0.34 0 0 0</pose>
          <geometry>
            <cylinder>
              <length>0.68000000000000005</length>
              <radius>0.050000000000000003</radius>
            </cylinder>
          </geometry>
          <material>
            <diffuse>1 0 0 1</diffuse>
            <ambient>1 0 0 1</ambient>
          </material>
        </visual>
        <enable_wind>false</enable_wind>
      </link>
      <joint name='link3_link4' type='revolute'>
        <pose>0 0 0 0 -0 0</pose>
        <parent>link_3</parent>
        <child>link_4</child>
        <axis>
          <xyz>0 1 0</xyz>
          <limit>
            <lower>-3.1400000000000001</lower>
            <upper>3.1400000000000001</upper>
            <effort>50</effort>
            <velocity>1000</velocity>
            <stiffness>100000000</stiffness>
            <dissipation>1</dissipation>
          </limit>
          <dynamics>
            <spring_reference>0</spring_reference>
            <spring_stiffness>0</spring_stiffness>
            <damping>0</damping>
            <friction>0</friction>
          </dynamics>
        </axis>
      </joint>
      <link name='link_4'>
        <pose>-2e-06 0.1 1.694 0 2.3e-05 1e-06</pose>
        <inertial>
          <pose>0 0 0 0 -0 0</pose>
          <mass>1.5</mass>
          <inertia>
            <ixx>0.0030500000000000002</ixx>
            <ixy>0</ixy>
            <ixz>0</ixz>
            <iyy>0.0030500000000000002</iyy>
            <iyz>0</iyz>
            <izz>0.0018749999999999999</izz>
          </inertia>
        </inertial>
        <collision name='link_4_collision'>
          <pose>0 0 0.065 0 0 0</pose>
          <geometry>
            <cylinder>
              <length>0.13</length>
              <radius>0.050000000000000003</radius>
            </cylinder>
          </geometry>
          <surface>
            <friction>
              <ode/>
            </friction>
            <bounce/>
            <contact/>
          </surface>
        </collision>
        <visual name='link_4_visual'>
          <pose>0 0 0.065 0 0 0</pose>
          <geometry>
            <cylinder>
              <length>0.13</length>
              <radius>0.050000000000000003</radius>
            </cylinder>
          </geometry>
          <material>
            <diffuse>1 1 0 1</diffuse>
            <ambient>1 1 0 1</ambient>
          </material>
        </visual>
        <enable_wind>false</enable_wind>
      </link>
      <joint name='link4_link5' type='revolute'>
        <pose>0 0 0 0 -0 0</pose>
        <parent>link_4</parent>
        <child>link_5</child>
        <axis>
          <xyz>1 0 0</xyz>
          <limit>
            <lower>-3.1400000000000001</lower>
            <upper>3.1400000000000001</upper>
            <effort>50</effort>
            <velocity>1000</velocity>
            <stiffness>100000000</stiffness>
            <dissipation>1</dissipation>
          </limit>
          <dynamics>
            <spring_reference>0</spring_reference>
            <spring_stiffness>0</spring_stiffness>
            <damping>0</damping>
            <friction>0</friction>
          </dynamics>
        </axis>
      </joint>
      <link name='link_5'>
        <pose>2e-06 0.1 1.874 1e-06 1.57002 1e-06</pose>
        <inertial>
          <pose>0 0 0 0 -0 0</pose>
          <mass>1</mass>
          <inertia>
            <ixx>0.0030330000000000001</ixx>
            <ixy>0</ixy>
            <ixz>0</ixz>
            <iyy>0.0030330000000000001</iyy>
            <iyz>0</iyz>
            <izz>0.00125</izz>
          </inertia>
        </inertial>
        <collision name='link_5_collision'>
          <pose>0 0 0.035 0 0 0</pose>
          <geometry>
            <cylinder>
              <length>0.17000000000000001</length>
              <radius>0.050000000000000003</radius>
            </cylinder>
          </geometry>
          <surface>
            <friction>
              <ode/>
            </friction>
            <bounce/>
            <contact/>
          </surface>
        </collision>
        <visual name='link_5_visual'>
          <pose>0 0 0.035 0 0 0</pose>
          <geometry>
            <cylinder>
              <length>0.17000000000000001</length>
              <radius>0.050000000000000003</radius>
            </cylinder>
          </geometry>
          <material>
            <diffuse>0 1 1 1</diffuse>
            <ambient>0 1 1 1</ambient>
          </material>
        </visual>
        <enable_wind>false</enable_wind>
      </link>
      <joint name='link5_tcp_connector' type='revolute'>
        <pose>0 0 0 0 -0 0</pose>
        <parent>link_5</parent>
        <child>tcp_connector</child>
        <axis>
          <xyz>0 0 1</xyz>
          <limit>
            <lower>-3.1400000000000001</lower>
            <upper>3.1400000000000001</upper>
            <effort>50</effort>
            <velocity>1000</velocity>
            <stiffness>100000000</stiffness>
            <dissipation>1</dissipation>
          </limit>
          <dynamics>
            <spring_reference>0</spring_reference>
            <spring_stiffness>0</spring_stiffness>
            <damping>0</damping>
            <friction>0</friction>
          </dynamics>
        </axis>
      </joint>
      <link name='tcp_connector'>
        <pose>0.120002 0.1 1.87409 -0 1.57002 -0</pose>
        <inertial>
          <pose>0 0 0 0 -0 0</pose>
          <mass>0.5</mass>
          <inertia>
            <ixx>0.00097499999999999996</ixx>
            <ixy>0</ixy>
            <ixz>0</ixz>
            <iyy>7.4999999999999993e-05</iyy>
            <iyz>0</iyz>
            <izz>0.00097499999999999996</izz>
          </inertia>
        </inertial>
        <collision name='tcp_connector_collision'>
          <pose>0 0 0.0125 0 0 0</pose>
          <geometry>
            <box>
              <size>0.03 0.15 0.03</size>
            </box>
          </geometry>
          <surface>
            <friction>
              <ode/>
            </friction>
            <bounce/>
            <contact/>
          </surface>
        </collision>
        <visual name='tcp_connector_visual'>
          <pose>0 0 0.0125 0 0 0</pose>
          <geometry>
            <box>
              <size>0.03 0.15 0.03</size>
            </box>
          </geometry>
          <material>
            <diffuse>1 1 1 1</diffuse>
            <ambient>1 1 1 1</ambient>
          </material>
        </visual>
        <enable_wind>false</enable_wind>
      </link>
      <joint name='tcp_connector_gripper_left' type='prismatic'>
        <pose>-0 0 0 0 -0 0</pose>
        <parent>tcp_connector</parent>
        <child>gripper_left</child>
        <axis>
          <xyz>0 1 0</xyz>
          <limit>
            <lower>-0.055</lower>
            <upper>0</upper>
            <effort>50</effort>
            <velocity>1000</velocity>
            <stiffness>100000000</stiffness>
            <dissipation>1</dissipation>
          </limit>
          <dynamics>
            <spring_reference>0</spring_reference>
            <spring_stiffness>0</spring_stiffness>
            <damping>0</damping>
            <friction>0</friction>
          </dynamics>
        </axis>
      </joint>
      <link name='gripper_left'>
        <pose>0.150002 0.165 1.87412 -0 1.57002 -0</pose>
        <inertial>
          <pose>0 0 0 0 -0 0</pose>
          <mass>0.20000000000000001</mass>
          <inertia>
            <ixx>0.00016799999999999999</ixx>
            <ixy>0</ixy>
            <ixz>0</ixz>
            <iyy>0.00016799999999999999</iyy>
            <iyz>0</iyz>
            <izz>3.0000000000000001e-06</izz>
          </inertia>
        </inertial>
        <collision name='gripper_left_collision'>
          <pose>0 0 0.05 0 0 0</pose>
          <geometry>
            <box>
              <size>0.01 0.01 0.1</size>
            </box>
          </geometry>
          <surface>
            <friction>
              <ode/>
            </friction>
            <bounce/>
            <contact/>
          </surface>
        </collision>
        <visual name='gripper_left_visual'>
          <pose>0 0 0.05 0 0 0</pose>
          <geometry>
            <box>
              <size>0.01 0.01 0.1</size>
            </box>
          </geometry>
          <material>
            <diffuse>0 0 0 1</diffuse>
            <ambient>0 0 0 1</ambient>
          </material>
        </visual>
        <enable_wind>false</enable_wind>
      </link>
      <joint name='tcp_connector_gripper_right' type='prismatic'>
        <pose>-0 0 0 0 -0 0</pose>
        <parent>tcp_connector</parent>
        <child>gripper_right</child>
        <axis>
          <xyz>0 1 0</xyz>
          <limit>
            <lower>0</lower>
            <upper>0.055</upper>
            <effort>50</effort>
            <velocity>1000</velocity>
            <stiffness>100000000</stiffness>
            <dissipation>1</dissipation>
          </limit>
          <dynamics>
            <spring_reference>0</spring_reference>
            <spring_stiffness>0</spring_stiffness>
            <damping>0</damping>
            <friction>0</friction>
          </dynamics>
        </axis>
      </joint>
      <link name='gripper_right'>
        <pose>0.150002 0.035 1.87412 -0 1.57002 -0</pose>
        <inertial>
          <pose>0 0 0 0 -0 0</pose>
          <mass>0.20000000000000001</mass>
          <inertia>
            <ixx>0.00016799999999999999</ixx>
            <ixy>0</ixy>
            <ixz>0</ixz>
            <iyy>0.00016799999999999999</iyy>
            <iyz>0</iyz>
            <izz>3.0000000000000001e-06</izz>
          </inertia>
        </inertial>
        <collision name='gripper_right_collision'>
          <pose>0 0 0.05 0 0 0</pose>
          <geometry>
            <box>
              <size>0.01 0.01 0.1</size>
            </box>
          </geometry>
          <surface>
            <friction>
              <ode/>
            </friction>
            <bounce/>
            <contact/>
          </surface>
        </collision>
        <visual name='gripper_right_visual'>
          <pose>0 0 0.05 0 0 0</pose>
          <geometry>
            <box>
              <size>0.01 0.01 0.1</size>
            </box>
          </geometry>
          <material>
            <diffuse>0 0 0 1</diffuse>
            <ambient>0 0 0 1</ambient>
          </material>
        </visual>
        <enable_wind>false</enable_wind>
      </link>
      <plugin name='gz_ros2_control::GazeboSimROS2ControlPlugin' filename='gz_ros2_control-system'>
        <parameters>/home/harshitji/robotic_arm_ws/install/robot_description/share/robot_description/config/controllers.yaml</parameters>
      </plugin>
      <initial_position xyz='0 0 0'/>
      <pose>0 0 0 0 -0 0</pose>
      <static>false</static>
      <self_collide>false</self_collide>
    </model>

    <light name='sun' type='directional'>
      <pose>0 0 10 0 -0 0</pose>
      <cast_shadows>true</cast_shadows>
      <intensity>1</intensity>
      <direction>-0.5 0.1 -0.9</direction>
      <diffuse>0.8 0.8 0.8 1</diffuse>
      <specular>0.2 0.2 0.2 1</specular>
      <attenuation>
        <range>1000</range>
        <linear>0.01</linear>
        <constant>0.90000000000000002</constant>
        <quadratic>0.001</quadratic>
      </attenuation>
      <spot>
        <inner_angle>0</inner_angle>
        <outer_angle>0</outer_angle>
        <falloff>0</falloff>
      </spot>
    </light>
  </world>
</sdf>
